version: '3'

services:
  openexcept:
    build: .
    ports:
      - "8000:8000"
    volumes:
      - ./:/app
    environment:
      - PYTHONDONTWRITEBYTECODE=1
      - PYTHONUNBUFFERED=1
      - POSTGRES_USER=openexcept
      - POSTGRES_PASSWORD=openexcept
      - POSTGRES_DB=openexcept
      - POSTGRES_HOST=postgres
    depends_on:
      - postgres
    command: ["./scripts/wait-for-it.sh", "postgres:5432", "--", "./scripts/start.sh"]

  postgres:
    image: ankane/pgvector:latest
    ports:
      - "5432:5432"
    environment:
      - POSTGRES_USER=openexcept
      - POSTGRES_PASSWORD=openexcept
      - POSTGRES_DB=openexcept
    volumes:
      - postgres_data:/var/lib/postgresql/data
    healthcheck:
      test: ["CMD-SHELL", "pg_isready -U openexcept"]
      interval: 5s
      timeout: 5s
      retries: 5

  grafana:
    image: grafana/grafana:10.2.0
    ports:
      - "3000:3000"
    volumes:
      - grafana_data:/var/lib/grafana
      - ./grafana/provisioning:/etc/grafana/provisioning
    environment:
      - GF_AUTH_ANONYMOUS_ENABLED=true
      - GF_AUTH_ANONYMOUS_ORG_ROLE=Admin
      - GF_USERS_ALLOW_SIGN_UP=false
    depends_on:
      - postgres

volumes:
  postgres_data:
  grafana_data: